{"trial_id": "00", "hyperparameters": {"space": [{"class_name": "Int", "config": {"name": "num_layers", "default": null, "conditions": [], "min_value": 1, "max_value": 3, "step": 1, "sampling": "linear"}}, {"class_name": "Int", "config": {"name": "units_0", "default": null, "conditions": [], "min_value": 32, "max_value": 128, "step": 16, "sampling": "linear"}}, {"class_name": "Float", "config": {"name": "learning_rate", "default": 0.0001, "conditions": [], "min_value": 0.0001, "max_value": 0.01, "step": null, "sampling": "log"}}, {"class_name": "Int", "config": {"name": "units_1", "default": null, "conditions": [], "min_value": 32, "max_value": 128, "step": 16, "sampling": "linear"}}], "values": {"num_layers": 2, "units_0": 32, "learning_rate": 0.0007487348419129488, "units_1": 32}}, "metrics": {"metrics": {}}, "score": null, "best_step": 0, "status": "FAILED", "message": "Traceback (most recent call last):\n  File \"/Library/Frameworks/Python.framework/Versions/3.10/lib/python3.10/site-packages/keras_tuner/engine/base_tuner.py\", line 270, in _try_run_and_update_trial\n    self._run_and_update_trial(trial, *fit_args, **fit_kwargs)\n  File \"/Library/Frameworks/Python.framework/Versions/3.10/lib/python3.10/site-packages/keras_tuner/engine/base_tuner.py\", line 235, in _run_and_update_trial\n    results = self.run_trial(trial, *fit_args, **fit_kwargs)\n  File \"/Library/Frameworks/Python.framework/Versions/3.10/lib/python3.10/site-packages/keras_tuner/engine/tuner.py\", line 287, in run_trial\n    obj_value = self._build_and_fit_model(trial, *args, **copied_kwargs)\n  File \"/Library/Frameworks/Python.framework/Versions/3.10/lib/python3.10/site-packages/keras_tuner/engine/tuner.py\", line 214, in _build_and_fit_model\n    results = self.hypermodel.fit(hp, model, *args, **kwargs)\n  File \"/Library/Frameworks/Python.framework/Versions/3.10/lib/python3.10/site-packages/keras_tuner/engine/hypermodel.py\", line 144, in fit\n    return model.fit(*args, **kwargs)\n  File \"/Library/Frameworks/Python.framework/Versions/3.10/lib/python3.10/site-packages/keras/utils/traceback_utils.py\", line 70, in error_handler\n    raise e.with_traceback(filtered_tb) from None\n  File \"/var/folders/wh/t_cp8dvx5d1_prfxzdfd9wnr0000gn/T/__autograph_generated_file62qkuy56.py\", line 15, in tf__train_function\n    retval_ = ag__.converted_call(ag__.ld(step_function), (ag__.ld(self), ag__.ld(iterator)), None, fscope)\nValueError: in user code:\n\n    File \"/Library/Frameworks/Python.framework/Versions/3.10/lib/python3.10/site-packages/keras/engine/training.py\", line 1284, in train_function  *\n        return step_function(self, iterator)\n    File \"/Library/Frameworks/Python.framework/Versions/3.10/lib/python3.10/site-packages/keras/engine/training.py\", line 1268, in step_function  **\n        outputs = model.distribute_strategy.run(run_step, args=(data,))\n    File \"/Library/Frameworks/Python.framework/Versions/3.10/lib/python3.10/site-packages/keras/engine/training.py\", line 1249, in run_step  **\n        outputs = model.train_step(data)\n    File \"/Library/Frameworks/Python.framework/Versions/3.10/lib/python3.10/site-packages/keras/engine/training.py\", line 1050, in train_step\n        y_pred = self(x, training=True)\n    File \"/Library/Frameworks/Python.framework/Versions/3.10/lib/python3.10/site-packages/keras/utils/traceback_utils.py\", line 70, in error_handler\n        raise e.with_traceback(filtered_tb) from None\n    File \"/Library/Frameworks/Python.framework/Versions/3.10/lib/python3.10/site-packages/keras/engine/input_spec.py\", line 298, in assert_input_compatibility\n        raise ValueError(\n\n    ValueError: Input 0 of layer \"sequential\" is incompatible with the layer: expected shape=(None, 28, 28), found shape=(None, 17)\n\n"}